Workbook

Sheet README
A1: Virginia System Levelized Cost of Energy (SLCOE) Model — 25-Year Comparison
A2: Two supply-mix scenarios for meeting projected Virginia (Dominion zone) electricity demand, 2026-2050
A4: SCOPE & PURPOSE
A6: This workbook builds an illustrative, fully-sourced, assumption-driven comparison of two supply portfolios for meeting Virginia's
A7: (Dominion zone) projected electricity demand through 2045+ (modeled 2026-2050), net of behind-the-meter solar that grows linearly
A8: to the statutory 6% net-metering cap. It is a directional planning-level tool, NOT a bankable IRP-grade or production-cost model.
A10: CRITICAL LIMITATIONS — READ BEFORE USING THESE NUMBERS
A12: 1. TRUE HOURLY DISPATCH, VERIFIED AGAINST REAL WEATHER. This model solves a genuine 8,760-hour linear program at each checkpoint
A13: year (2030/2035/2040/2044.5), using actual historical hourly weather -- not a typical/average year, and not an annual GWh
A14: balance. The design weather year (Apr 2016-Mar 2017) was chosen because it contains a sustained multi-week low-solar/low-wind
A15: event, verified as the min-max-robust choice against two other tested severe-weather years (2013-14 Polar Vortex, 2012-13
A16: acute insolation lull). Storage state-of-charge and solar's daily/seasonal shape are modeled directly, not assumed away.
... A45: Summary — headline GW/GWh answers and side-by-side SLCOE comparison

Sheet Assumptions & Sources
A1: Master Assumptions & Sources
A3: Category | B3: Assumption | C3: Value | D3: Notes | E3: Source
A4: Demand | B4: 2025 Virginia total system generation, baseline (GWh) | C4: 110,000 | D4: Approx.; 2025 statewide generation mix sums to ~107,434 GWh; rounded up slightly for sales+losses+imports. | E4: EIA-based; Wikipedia 'List of power stations in Virginia', 2025 generation mix table
A5: Demand | B5: 2025 Dominion (DOM) zone summer peak load (MW) | C5: 23,905 | D5: Actual 2025 summer peak. | E5: EIA 'Commercial electricity sales have soared in Virginia' (May 2026), citing EIA-930 Hourly Electric Grid Monitor
A6: Demand | B6: Demand growth rate, 2026-2035 | C6: 5.5%/yr | D6: Dominion's own stated 10-yr forward growth rate. | E6: Dominion 2025 IRP, as reported by ReisingerGooch: 'demand...will grow 5.5% annually for the next decade and double by 2039'
A7: Demand | B7: Demand growth rate, 2036-2039 | C7: ~4.0%/yr | D7: Derived: rate needed for cumulative doubling by 2039 given 5.5%/yr through 2035. | E7: Derived from Dominion's 'double by 2039' statement (same source)
A8: Demand | B8: Demand growth rate, 2040-2050 | C8: 2.5%/yr | D8: Assumed moderation as data-center buildout matures; judgment call, not a cited Dominion figure. | E8: Model assumption — bounds cumulative 2025-2045 growth near the 121-183% range bracketed by cited sources below
A9: Demand | B9: Cross-check: DOM zone peak growth 2025-2045 | C9: +121% | D9: PJM's own 20-year forecast for the DOM zone specifically (peak load, not energy). | E9: American Action Forum, citing PJM 2026 Long-Term Load Forecast Report
A10: Demand | B10: Cross-check: VA total demand growth 2023-2040 | C10: +183% | D10: Higher, energy-basis (not peak) Dominion IRP figure; higher because it includes full data-center ramp through 2040 vs PJM's smoother 20-yr peak curve. | E10: American Action Forum, citing Dominion Energy 2025 IRP Update
A11: Net Metering | B11: Statutory net-metering cap | C11: 6% of prior-year peak load | D11: Raised from 1% under 2020 VCEA; 1 of the 6 points reserved for low-to-moderate-income participants. | E11: Va. Code §56-594; CCAN Action Fund VCEA fact sheet
A12: Net Metering | B12: 2026 starting NEM-enrolled solar capacity (MW) | C12: 500 | D12: Illustrative starting point for the linear ramp; actual current NEM-specific enrollment (as opposed to all distributed/community solar) is not separately published at this granularity. | E12: Model assumption, bounded by VA total installed DG solar context (SEIA: VA is 9th-largest solar market, 7.5 GW total, of which ~5.3 GW is utility-scale per Cleanview, February 2026)
A13: Net Metering | B13: NEM distributed solar capacity factor | C13: 20% | D13: Lower than utility-scale tracking solar; reflects fixed-tilt rooftop orientation mix. | E13: NREL PVWatts typical range for mid-Atlantic fixed-tilt systems
A14: Financial | B14: Real discount rate (WACC, real) | C14: 4.5% | D14: Approximates Dominion's allowed capital structure/ROE (~9.6-10% nominal ROE, ~50/50 debt/equity) less ~2.5% assumed inflation. | E14: Model assumption based on typical Virginia SCC-allowed utility ROE range; not a specific SCC order figure
... A25: Offshore Wind (CVOW) | B25: CVOW nameplate capacity | C25: 2,600 MW (2,587 MW approved) | D25: 176 turbines; began delivering power March 23, 2026; full completion expected early 2027. | E25: BOEM Record of Decision; Utility Dive, March 2026
A26: Offshore Wind (CVOW) | B26: CVOW capacity factor | C26: 42% | E26: Wikipedia 'Coastal Virginia Offshore Wind'
A27: Offshore Wind (CVOW) | B27: CVOW levelized cost of energy | C27: $91/MWh (2027$) | D27: Dominion-disclosed project LCOE as of Feb 2025, based on ~$8.7B capital cost excluding onshore transmission. | E27: Lazard LCOE+ (June 2025), citing Dominion's public disclosure
A28: Offshore Wind (CVOW) | B28: CVOW-dedicated onshore/offshore transmission upgrade cost | C28: $400/kW | D28: Full CVOW deliverability requires separate PJM transmission upgrades; no public $/kW figure found for Virginia specifically — this is a general offshore-wind transmission benchmark, not Dominion-specific. | E28: Model assumption; general offshore wind interconnection cost literature (NREL/LBNL offshore wind cost benchmarks); context: Utility Dive reports full deliverability 'depends on transmission upgrades in PJM'
A29: New Solar (Scenario 1) | B29: New utility solar CAPEX (2026, $/kW-AC) | C29: $1,474/kW | D29: Declining at 1.5%/yr real per NREL ATB moderate-case trend. Base value derived from Lazard Low/High cases ($1,150/kW @ 30% CF; $1,600/kW @ 20% CF) linearly interpolated to VA's actual blended capacity factor (22.8%, from this model's own PVWatts data). Corroborated by NREL ATB 2024 base year ($1.43/WAC in 2022, single-axis tracking) projected to 2026. | E29: Lazard LCOE+ v18.0 (June 2025), interpolated to VA capacity factor; corroborated by NREL ATB 2024 -- see Scenario1 cell comment for full derivation
A30: New Solar (Scenario 1) | B30: Real capital cost decline rate | C30: 1.5%/yr | E30: NREL ATB moderate-scenario-style decline assumption
A31: Storage — Sodium-ion (short-duration) | B31: 2026 system CAPEX ($/kWh) | C31: $97.50/kWh | D31: Proxy: 'near cost parity with LFP Li-ion today' (ESS-News/ScienceDirect); LFP system cost benchmark $85-110/kWh, midpoint used. | E31: Kucher et al., 'Sodium-ion battery cost projections and their impact on the global energy system transition until 2050,' ScienceDirect (2025/2026); cross-referenced against energy-solutions.co LFP benchmark table
A32: Storage — Sodium-ion (short-duration) | B32: 2050 system CAPEX ($/kWh) | C32: $43.40/kWh | D32: Paper's own projected utility-scale battery system capex range: EUR28.5-51.9/kWh by 2050 (~EUR40.2 midpoint), converted at ~1.08 USD/EUR. | E32: Same ScienceDirect paper
A33: Storage — Sodium-ion (short-duration) | B33: Assumed duration | C33: 6 hours | D33: Per your instruction to use a mix of durations aside from 4 hours; sodium-ion targets the daily-cycling/short-duration role (paper notes SIB competitive for stationary/daily-cycling applications). | E33: Model assumption, informed by source
A34: Storage — Sodium-ion (short-duration) | B34: Cost decline shape 2026-2050 | C34: Exponential, smooth | D34: Interpolated exponential decline from 2026 to 2050 anchor values (not the 1/4-factor rule, which is applied to iron-air specifically per your instruction). | E34: Model methodology
A35: Storage — Sodium-ion (short-duration) | B35: Round-trip efficiency | C35: 90% | D35: Model parameter (NA_RTE_CHARGE in lp_model.py) used in every hourly LP solve -- charge-side round-trip efficiency, consistent with typical lithium-ion-class battery chemistry benchmarks. | E35: Model assumption -- general Li-ion-class storage benchmark, not sodium-ion-specific primary sourcing
A36: Storage — Iron-air (long-duration/LDES) | B36: 2026 turnkey system CAPEX ($/kWh) | C36: $52.50/kWh | D36: Midpoint of Form Energy-based 'turnkey system cost (2026)' range of $45-60/kWh. | E36: Energy Solutions Intelligence, 'Iron-Air Batteries 2026: 100-Hour Storage at Under $20/kWh,' July 2026 (energy-solutions.co)
A37: Storage — Iron-air (long-duration/LDES) | B37: Cost decline rule | C37: Exponential decline to 1/4 of 2026 value by 2050 | D37: Per your explicit instruction. 2050 value = $52.50/4 = $13.13/kWh. Note: the source article's OWN roadmap is more front-loaded (cost 'approaching $15/kWh' already by its 2030 milestone) — the smooth 2026-2050 exponential-to-1/4 path used here is more gradual than the source's own trajectory; flagged for transparency. | E37: Same source; formula = 2026 value x (0.25)^((year-2026)/24)
A38: Storage — Iron-air (long-duration/LDES) | B38: Assumed duration | C38: 100 hours | D38: Per source: Form Energy systems target 100+ hour continuous discharge; Dominion Energy itself has a 5MW/500MWh (100-hr) iron-air pilot slated for 2027. | E38: Same source
A39: Storage — Iron-air (long-duration/LDES) | B39: Round-trip efficiency -- ACTUAL VALUE USED | C39: 80% (was shown as 40-50% informational, now corrected) | D39: CORRECTED: the source material's own round-trip efficiency figure (40-50%) was previously shown here marked 'informational; not separately modeled' -- but this was misleading. The model's actual FE_RTE_CHARGE parameter (used in every hourly LP solve, via iron_air_rte(2044.5) in lp_model.py) is 80%, a materially different, real dispatch parameter -- not merely informational. The 40-50% source figure and the 80% model parameter are NOT the same number; this row previously implied the lower figure was simply unused, when in fact a different, higher figure was driving every solve without being disclosed here. | E39: Model parameter (lp_model.py, iron_air_rte function) -- see code for the underlying assumption; NOT independently re-derived from the original Form Energy source material for this specific figure
A40: Storage — Technology mix | B40: Short-duration (sodium-ion) vs. long-duration (iron-air) split | C40: 82.1% / 17.9% | D40: Derived directly from the 2026-enacted VCEA storage split: 16,000 MW short-duration / 4,000 MW LDES (Dominion, CORRECTED from an earlier 3,480 MW figure per Va. Code 56-585.5(E)(4)) = 80.0%/20.0%. Applied consistently to Scenario 1/1B's co-located storage and Scenario 2's VCEA-minimum storage build. | E40: Ratio derived from Va. Code 56-585.5(E)(4), 2026-enacted (HB895/SB448)
A41: Storage — Technology mix | B41: Fixed O&M (both sodium-ion and iron-air) | C41: 2.5% of CAPEX/yr | D41: Model parameter (STOR_FOM_PCT in lp_model.py), applied uniformly to both storage technologies -- same rate multiplies each technology's own energy CAPEX. Confirmed via direct code inspection to apply identically to both, not technology-specific. | E41: Model assumption -- general storage O&M benchmark, not independently sourced per technology
A42: Storage — Bath County Pumped Hydro (existing) | B42: Nameplate capacity | C42: 3,000 MW | D42: Existing Dominion pumped-storage hydroelectric facility (widely reported as the world's largest pumped-storage facility by generating capacity); modeled as a fixed, already-built resource, not part of any scenario's new-build decision. | E42: Model assumption -- round-number figure close to Bath County's publicly reported ~3,003 MW nameplate; not independently re-verified against a specific primary source in this project.
... A71: VCEA/RPS Statutory Minimums (Scenario 2) | B71: Solar + onshore wind target by 2035 | C71: 16,100 MW | D71: Must include 1,100 MW of distributed solar (<=3MW projects); 35% must be non-utility-owned. | E71: Va. Code §56-585.5(D)(2), as codified
A72: VCEA/RPS Statutory Minimums (Scenario 2) | B72: CONFIRMED STALE: current buildout uses simple straight-line ramp, not statute's actual interim milestones | C72: 2027: 6,000 MW (ours: 1,789); 2030: 10,000 MW (ours: 7,156)
A73: VCEA/RPS Statutory Minimums (Scenario 2) | B73: Offshore wind 'public interest' declaration | C73: 5,200 MW by 2035 | D73: Not included in Scenario 2's supply stack per the user's scenario description (Scenario 2 = solar+storage minimum + CCGT only); CVOW (2.6 GW of this 5.2 GW) appears only in Scenario 1. | E73: Va. Code §56-585.5(D)(2); CCAN Action Fund VCEA fact sheet
A74: VCEA/RPS Statutory Minimums (Scenario 2) | B74: Energy storage target (Dominion) actually used in Scenario 2 | C74: 16,000 MW short-duration + 4,000 MW LDES by 2045 | D74: CORRECTED: Scenario 2 uses the 2026-enacted targets (this row), NOT the original 2,700 MW-by-2035 floor described in an earlier version of this model. LDES figure corrected from an earlier 3,480 MW to the confirmed 4,000 MW per Va. Code 56-585.5(E)(4). | E74: Va. Dept. of Planning & Budget, 2026 General Assembly fiscal impact statement (HB895/SB448); Williams Mullen legal alert, May 2026; Va. Code 56-585.5(E)(4)
A75: VCEA/RPS Statutory Minimums (Scenario 2) | B75: ASSUMPTION: statutory 'petitioned for' storage milestone treated as installed capacity | C75: 4,000 MW by 2030 (ours: 3,368 MW, gap ~632 MW)
A76: VCEA/RPS Statutory Minimums (Scenario 2) | B76: Combined Dominion total (short + LDES) | C76: 20,000 MW by 2045 | D76: This is a ~7.2x increase over the original 2,700 MW target — NOT a doubling. (Statewide combined Dominion+APCo total is reported elsewhere as ~21,000 MW.) Flagging this because the request described it as 'doubled'; using the correct enacted figures per your instruction to 'use the 2026 amount.' | E76: Va. Dept. of Planning & Budget fiscal impact statement; Virginia Center for Investigative Journalism/WHRO, July 2026 ('sevenfold buildout from the 3,100 MW initially required')
A77: Hourly LP Model Mechanics | B77: Unserved-energy shadow penalty | C77: $100,000/MWh | D77: Used throughout every hourly LP solve to represent the cost of failing to serve demand -- makes the model always prefer meeting load over any feasible alternative, while keeping the problem solvable rather than hard-infeasible when a fixed design genuinely cannot meet a test year's demand. | E77: Model parameter (UNSERVED_PENALTY in lp_model.py), matching literature convention (e.g. "Preparing for the Worst," 2025)
A78: Hourly LP Model Mechanics | B78: Export/transmission cap | C78: 5,000 MW | D78: Finite limit on how much surplus clean generation can be exported/sold in any hour, used throughout the hourly LP. This is a modeling assumption to resolve solver degeneracy (unbounded arbitrage from a finite export price against unlimited volume), NOT a Dominion-specific transmission study figure -- see Appendix A for the disclosed limitation and the finding that this cap is saturated (>4,900 of 5,000 MW) in 82% of hours in at least one tested checkpoint. | E78: Model assumption (EXPORT_CAP_MW in lp_model.py); see Appendix A for full disclosure
A79: Hourly LP Model Mechanics | B79: Scenario 2 export capability | C79: Disabled (bounded to zero) | D79: Scenario 2's CCGT exists to serve Dominion's own load-serving-entity demand, not to operate as a merchant exporter. An earlier version of this solve carried over Scenario 1/3's export mechanism without reconsidering fit -- diagnosed and corrected after finding gas dispatch was identical regardless of demand or clean capacity (the tell of pure arbitrage), confirmed via zero curtailment even with export disabled (ruling out genuine overgeneration). Gas dispatch dropped 40-53% after the fix. | E79: Model correction, documented fully in the Scenario2_Base tab's own methodology note
...

Sheet Summary
A1: SUMMARY — Virginia SLCOE Comparison
A3: Q1 — GW OF SOLAR AND GW/GWh OF ENERGY STORAGE (as of 2025/current)
A4: Total Virginia installed solar capacity (all segments) | B4: 7.5 GW | E4: SEIA: Virginia is the nation's 9th-largest solar market, 7.5 GW of capacity (as of early 2026 reporting)
A5: of which utility-scale solar | B5: 5.3 GW | D5: 143 operating solar farms | E5: Cleanview Virginia Solar Farm Map & Project List, July 2026
A6: of which distributed/rooftop/community (implied residual) | B6: ~2.2 GW | E6: Model-derived residual: 7.5 GW total minus 5.3 GW utility-scale
A7: UPDATED: blended solar capacity factor used in this model | B7: 22.8% | D7: Computed from 6 uploaded hourly PVWatts-style files (Chesapeake City, Albemarle County, King George County; 2016+2017). Site-year range 21.8%-23.4%. Replaces prior generic 24-25% benchmark. | E7: User-provided hourly insolation files; computed in-model
A9: Existing PUMPED-HYDRO storage (Bath County Pumped Storage Station) | B9: 3,000 MW | D9: Operational since 1985; ~10-11 hr typical duration implies roughly 30+ GWh (not separately published; general convention, not an exact cited figure) | E9: VPM/WHRO reporting, Aug 2025
A10: Existing/near-term BATTERY storage (sum of operating + financed projects) | B10: ~260 MW / ~660+ MWh | D10: Scott (12MW), Dry Bridge (20MW), Dulles (50MW planned), 3 pilots (~26MW/~58MWh), Prospect Power (150MW/600MWh, financed 2026) | E10: Dominion Energy 'Battery Storage' page; VPM; StockTitan/PR Newswire, 2026
A12: UPDATED STATUTORY STORAGE TARGETS (2026-enacted, HB895/SB448, effective 7/1/2026):
A13: Dominion short-duration (sodium-ion proxy) target | B13: 16,000 MW by 2045 | D13: Up from original 2,700 MW/2035 — a ~7.2x increase (NOT a doubling — see Assumptions tab note) | E13: Va. Dept. of Planning & Budget fiscal impact statement; Williams Mullen, May 2026
A14: Dominion long-duration/LDES (iron-air proxy) target | B14: 3,480 MW by 2045 | D14: New category; VCEA previously had no LDES-specific target | E14: Same sources
A15: Dominion combined total (used in this model's Scenario 2) | B15: 19,480 MW by 2045 | D15: Statewide combined Dominion+APCo total reported elsewhere as ~21,000 MW | E15: VCIJ/WHRO, July 2026
A17: STORAGE TECHNOLOGY COSTS used in this model (replacing prior lithium-ion benchmark):
A18: Sodium-ion (short-duration, 6-hr assumed) | B18: $97.50/kWh (2026) -> $43.40/kWh (2050) | D18: Smooth exponential decline | E18: Kucher et al., ScienceDirect, 'Sodium-ion battery cost projections...to 2050' (2025/2026)
A19: Iron-air (long-duration/LDES, 100-hr assumed) | B19: $52.50/kWh (2026) -> $13.13/kWh (2050) | D19: Exponential decline to exactly 1/4 of 2026 value by 2050, per your specified formula | E19: Energy Solutions Intelligence, 'Iron-Air Batteries 2026...' (energy-solutions.co), July 2026
A21: Q2 — SYSTEM LEVELIZED COST OF ENERGY (SLCOE), 25-YEAR (2026-2050), $/MWh
A22: Scenario | B22: SLCOE ($/MWh) | C22: vs. Scenario 1 | D22: What it represents
A23: Scenario 1 — Utility solar+storage (VPP-firmed) + nuclear + existing solar + CVOW [REMOVED -- superseded by HourlyRPS tabs]
A24: Scenario 2 — VCEA/RPS-minimum solar+storage + CCGT (BASE case = Deloitte gas price) [REMOVED -- superseded by HourlyRPS tabs]
A25: Scenario 2 — same build, EIA gas price (informational reference only, not primary) [REMOVED -- superseded by HourlyRPS tabs]
A26: Scenario 3 — Scenario 1's new-build split 80% utility/10% rooftop/10% parking-lot + DSM suite [REMOVED -- superseded by HourlyRPS tabs]
A27: Scenario 1B (Hourly) — 95% clean/5% gas, TRUE hourly LP dispatch (DIFFERENT METHODOLOGY, see Scenario1B tab) | B27: =Scenario1B!B49 -> 37.604352 | C27: n/a — not on the same 25-yr PV basis, see Scenario1B tab | D27: 2044/2045 point-in-time snapshot verified against actual 2016/2017 weather (incl. the Dec-Feb Dunkelflaute-style event), NOT a 2026-2050 build-out. Nominal $/MWh shown; see Scenario1B tab for the properly-discounted NPV and all-in (incl. Tier 1/2) figures.
A28: Scenario 3B (Hourly) — Scenario1B's mechanics + Scenario 3's DSM-adjusted demand (DIFFERENT METHODOLOGY, see Scenario3B tab) | B28: =Scenario3B!B50 -> 36.799603 | C28: n/a — not on the same 25-yr PV basis, see Scenario3B tab | D28: Same true hourly LP as Scenario1B, same 95%/5% gas cap, but demand reduced per Scenario 3's DSM suite (peak-targeted hourly allocation, see Scenario3B tab). SLCOE-equivalent ~37% below Scenario1B's, driven disproportionately by reduced extreme-event storage need, not just less total demand.
A31: Q3 — HOURLY DISPATCH VERIFICATION RESULTS (Scenario 1 & Scenario 1B, hourly-resolved, 2044/2045 actual weather)
A32: Methodology note: unlike Scenarios 1/2/3 above (25-yr levelized SLCOE from an annual energy-balance model), these results come from a true hourly
A33: linear-programming dispatch of 17,544 hours (2044 using actual 2016 weather, 2045 using actual 2017 weather -- including the Dec/Jan/Feb low-solar event),
A34: sizing solar/sodium-ion/iron-air capacity to reliably serve Dominion-territory hourly load. Figures are a 2044/2045 point-in-time capacity-adequacy snapshot,
A35: not a full 2026-2050 build-out -- NOT directly comparable to the $/MWh SLCOE figures above without care. NPV uses the same 4.5% real WACC and discounting convention.
A36: Scenario 1's cost figures use the annual model's updated $63/MWh export price base (was $45), applied as a POST-HOC revenue recalculation on the ORIGINAL
A37: $45-price-optimal dispatch/build decisions (build sizes NOT re-optimized against the new price) -- a genuine LP re-solve at $63/MWh was attempted and hit an
A38: unresolved solver issue (see chat history); this is a directional approximation, not a fully re-optimized result. Build sizes below are therefore unchanged from the original $45-price solve.
A40: Metric | B40: Scenario 1 (100% clean, no gas) | C40: Scenario 1B (95% clean / 5% gas)
A41: New solar built (MW) | B41: 121,102 (unchanged, not re-optimized) | C41: 74,445
A42: Sodium-ion power / energy / duration | B42: 146,161 MW / 534,741 MWh / 3.7 hr | C42: 147,326 MW / 319,164 MWh / 2.2 hr
A43: Iron-air (LDES) energy / power (100-hr fixed duration) | B43: 2,482,500 MWh / 24,825 MW | C43: 363,374 MWh / 3,634 MW
A44: Gas generation used (2-yr total) | B44: 0 GWh (hard constraint) | C44: 24,804 GWh
A45: Tier 1 climate cost of that gas (CCGT factors, 2-yr total) | B45: $0 (no gas) | C45: $1,601M
A46: Tier 2 health cost of that gas (suburban-avg, sustained; CCGT factors) | B46: $0 (no gas) | C46: $685M
A47: 2-yr nominal total cost | B47: $25.46B (was $26.87B at old $45 export price) | C47: $14.49B (at old $45 export price -- not yet updated)
A48: NPV (2026 dollars, 4.5% real WACC) | B48: $10.79B (was $11.39B) | C48: $6.14B (at old $45 export price -- not yet updated)
...

Sheet Demand_NEM
A1: Virginia Demand Forecast & 6% Net-Metering Cap Carve-Out
A3: Line Item | B3: Input / Source | C3: 2026 | D3: 2027 | E3: 2028 | F3: 2029 | G3: 2030 | H3: 2031 | I3: 2032 | J3: 2033 | K3: 2034 | L3: 2035 | M3: 2036 | N3: 2037 | O3: 2038 | P3: 2039 | Q3: 2040 | R3: 2041 | S3: 2042 | T3: 2043 | U3: 2044 | V3: 2045 | W3: 2046 | X3: 2047 | Y3: 2048 | Z3: 2049 | AA3: 2050
A5: STEP 1 — TOTAL VIRGINIA (DOM ZONE) SYSTEM DEMAND
A6: 2025 baseline system demand (GWh) | B6: 110000
A7: Demand growth rate (%/yr) | B7: 5.5% (2026-35), ~4.0% (2036-39), 2.5% (2040-50) — see Assumptions tab | C7: 0.055 | D7: 0.055 | E7: 0.055 | F7: 0.055 | G7: 0.055 | H7: 0.055 | I7: 0.055 | J7: 0.055 | K7: 0.055 | L7: 0.055 | M7: 0.0396 | N7: 0.0396 | O7: 0.0396 | P7: 0.0396 | Q7: 0.025 | R7: 0.025 | S7: 0.025 | T7: 0.025 | U7: 0.025 | V7: 0.025 | W7: 0.025 | X7: 0.025 | Y7: 0.025 | Z7: 0.025 | AA7: 0.025
A8: Total Virginia system demand (GWh) | C8: =$B$6*(1+C7) -> 116050 | D8: =C8*(1+D7) -> 122432.75 | E8: =D8*(1+E7) -> 129166.55 | F8: =E8*(1+F7) -> 136270.71 | G8: =F8*(1+G7) -> 143765.6 | H8: =G8*(1+H7) -> 151672.71 | I8: =H8*(1+I7) -> 160014.71 | J8: =I8*(1+J7) -> 168815.52 | K8: =J8*(1+K7) -> 178100.37 | ... AA8: =Z8*(1+AA7) -> 287968.43
A10: STEP 2 — DOM ZONE PEAK LOAD & STATUTORY 6% NET-METERING CAP (Va. Code Section 56-594)
A11: 2025 baseline DOM zone summer peak (MW) | B11: 23905
A12: DOM zone summer peak load (MW) | C12: =$B$11*(1+C7) -> 25219.775 | D12: =C12*(1+D7) -> 26606.863 | E12: =D12*(1+E7) -> 28070.24 | F12: =E12*(1+F7) -> 29614.103 | G12: =F12*(1+G7) -> 31242.879 | H12: =G12*(1+H7) -> 32961.237 | I12: =H12*(1+I7) -> 34774.105 | J12: =I12*(1+J7) -> 36686.681 | K12: =J12*(1+K7) -> 38704.449 | ... AA12: =Z12*(1+AA7) -> 62580.776
A13: Statutory net-metering cap (% of peak) | B13: 0.06 | C13: =$B$13 -> 0.06 | D13: =$B$13 -> 0.06 | E13: =$B$13 -> 0.06 | F13: =$B$13 -> 0.06 | G13: =$B$13 -> 0.06 | H13: =$B$13 -> 0.06 | I13: =$B$13 -> 0.06 | J13: =$B$13 -> 0.06 | ... AA13: =$B$13 -> 0.06
A14: 6% NEM cap, capacity-equivalent (MW) | C14: =C12*C13 -> 1513.1865 | D14: =D12*D13 -> 1596.4118 | E14: =E12*E13 -> 1684.2144 | F14: =F12*F13 -> 1776.8462 | G14: =G12*G13 -> 1874.5727 | H14: =H12*H13 -> 1977.6742 | I14: =I12*I13 -> 2086.4463 | J14: =J12*J13 -> 2201.2009 | ... AA14: =AA12*AA13 -> 3754.8466
A16: STEP 3 — NEM-ENROLLED DISTRIBUTED SOLAR (linear ramp to cap by 2035, then tracks the growing cap)
A17: 2026 starting NEM-enrolled solar capacity (MW) | B17: 500
A18: NEM-enrolled solar capacity, cumulative (MW) | C18: =$B$17+(L14-$B$17)*0/9 -> 500 | D18: =$B$17+(L14-$B$17)*1/9 -> 716.66573 | E18: =$B$17+(L14-$B$17)*2/9 -> 933.33147 | F18: =$B$17+(L14-$B$17)*3/9 -> 1149.9972 | G18: =$B$17+(L14-$B$17)*4/9 -> 1366.6629 | H18: =$B$17+(L14-$B$17)*5/9 -> 1583.3287 | I18: =$B$17+(L14-$B$17)*6/9 -> 1799.9944 | J18: =$B$17+(L14-$B$17)*7/9 -> 2016.6601 | K18: =$B$17+(L14-$B$17)*8/9 -> 2233.3259 | L18: =$B$17+(L14-$B$17)*9/9 -> 2449.9916 | M18: =M14 -> 2547.0113 | N18: =N14 -> 2647.8729 | O18: =O14 -> 2752.7287 | P18: =P14 -> 2861.7367 | Q18: =Q14 -> 2933.2802 | R18: =R14 -> 3006.6122 | S18: =S14 -> 3081.7775 | T18: =T14 -> 3158.8219 | ... AA18: =AA14 -> 3754.8466
A19: NEM solar capacity factor (%) | B19: 0.228 | C19: =$B$19 -> 0.228 | D19: =$B$19 -> 0.228 | E19: =$B$19 -> 0.228 | F19: =$B$19 -> 0.228 | G19: =$B$19 -> 0.228 | H19: =$B$19 -> 0.228 | I19: =$B$19 -> 0.228 | J19: =$B$19 -> 0.228 | ... AA19: =$B$19 -> 0.228
A20: NEM solar generation (GWh) | C20: =C18*C19*8.76 -> 998.64 | D20: =D18*D19*8.76 -> 1431.3821 | E20: =E18*E19*8.76 -> 1864.1243 | F20: =F18*F19*8.76 -> 2296.8664 | G20: =G18*G19*8.76 -> 2729.6085 | H20: =H18*H19*8.76 -> 3162.3507 | I20: =I18*I19*8.76 -> 3595.0928 | J20: =J18*J19*8.76 -> 4027.8349 | ... AA20: =AA18*AA19*8.76 -> 7499.48
A22: STEP 4 — NET UTILITY-SERVED DEMAND (total demand, net of NEM solar carve-out; feeds Scenario 1 & Scenario 2)
A23: Net utility-served demand (GWh) | C23: =C8-C20 -> 115051.36 | D23: =D8-D20 -> 121001.37 | E23: =E8-E20 -> 127302.43 | F23: =F8-F20 -> 133973.85 | G23: =G8-G20 -> 141035.99 | H23: =H8-H20 -> 148510.36 | I23: =I8-I20 -> 156419.61 | J23: =J8-J20 -> 164787.68 | ... AA23: =AA8-AA20 -> 280468.95

Sheet Externality_SocialCost
A1: Social Cost of DLC-with-Onsite-Backup-Generation — Three-Tier Externality Analysis
A2: Illustrative case: Ashburn-style data-center backup diesel generation during PJM emergency demand response events
A4: DIESEL BACKUP GENERATOR EMISSION FACTORS (per MWh generated)
A5: Note: light citizen-readable summary is in Section F at the bottom of this tab.
A6: CO2 emission factor (ton/MWh) | B6: 0.52
A7: NOx emission factor (ton/MWh) | B7: 0.007
A8: PM2.5 emission factor (ton/MWh) | B8: 0.0002
A9: SO2 emission factor (ton/MWh) | B9: 5e-05
A11: TIER 1 — CLIMATE COSTS (pre-Jan 20, 2025 EPA SC-GHG methodology; see Assumptions tab for governance note)
A12: SC-CO2, low (2.5% discount rate) ($/ton) | B12: 140
A13: SC-CO2, central (2.0% discount rate) ($/ton) | B13: 190
A14: SC-CO2, high (1.5% discount rate) ($/ton) | B14: 380
A15: SC-CH4 ($/ton) [reference only -- negligible for diesel combustion] | B15: 1600
A16: SC-N2O ($/ton) [reference only -- negligible for diesel combustion] | B16: 5400
A18: Tier 1 cost per MWh, by discount-rate case ($/MWh)
A19: Low (2.5% discount) | B19: =$B$6*$B$12 -> 72.8
A20: Central (2.0% discount) | B20: =$B$6*$B$13 -> 98.8
A21: High (1.5% discount) | B21: =$B$6*$B$14 -> 197.6
A23: TIER 2 — REGIONAL/LOCAL HEALTH COSTS (EPA Benefit-per-Ton, 'area source' category, 2016$)
A24: PM2.5 benefit-per-ton, base ($/ton) | B24: 350000
A25: SO2 benefit-per-ton, base ($/ton) | B25: 54000
A26: NOx benefit-per-ton, base ($/ton) | B26: 8600
A28: Tier 2 base cost per MWh (before density/frequency sensitivity), $/MWh
A29: PM2.5 + SO2 + NOx, base area-source rates | B29: =$B$8*$B$24+$B$9*$B$25+$B$7*$B$26 -> 132.9
A31: SENSITIVITY DIMENSION 1 — POPULATION DENSITY MULTIPLIER (Tier 2 only; illustrative, see Assumptions tab)
A32: Rural Dominion-territory multiplier | B32: 0.25
A33: Suburban-average multiplier | B33: 1
A34: Dense/Ashburn-type multiplier | B34: 1.75
A36: SENSITIVITY DIMENSION 2 — EVENT FREQUENCY/DURATION MULTIPLIER (Tier 2 only)
A37: Episodic (current occasional-event basis) multiplier | B37: 1
A38: Sustained (if events become routine) multiplier | B38: 10
A41: COMBINED SENSITIVITY GRID -- Tier 2 health cost, $/MWh (density x frequency; Tier 1 climate cost shown separately per presentation principle)
A42: Per the 'never pre-blend Tier 1 and Tier 2' principle (Assumptions tab), this grid is Tier-2 (health) ONLY. Tier 1 (climate) totals are fixed regardless of density/frequency and shown in the row below.
A43: Density \ Frequency | B43: Episodic (current) | C43: Sustained (if routine)
A44: Rural | B44: =$B$29*$B$32*$B$37 -> 33.225 | C44: =$B$29*$B$32*$B$38 -> 332.25
A45: Suburban-average | B45: =$B$29*$B$33*$B$37 -> 132.9 | C45: =$B$29*$B$33*$B$38 -> 1329
A46: Dense (Ashburn-type) | B46: =$B$29*$B$34*$B$37 -> 232.575 | C46: =$B$29*$B$34*$B$38 -> 2325.75
A48: Tier 1 (climate) cost per MWh -- fixed regardless of density/frequency, shown for reference alongside the grid above
A49: Central estimate | B49: =$B$20 -> 98.8
A50: Range (low discount rate to high discount rate) | B50: =$B$19 -> 72.8 | C50: =$B$21 -> 197.6
...

Sheet Scenario1
A1: Scenario 1 — Hourly-Verified, RPS-Compliance Trajectory (2026-2045)
A2: Genuine hourly LP re-solve at each checkpoint, following Dominion's actual RPS schedule, at current cost assumptions
A4: METHODOLOGY NOTE — read before using this tab
A5: DISTINCT from both Scenario1 (CF-based annual model) and Scenario1B (fixed 5% gas snapshot, 2044/45 only). This tab follows the ACTUAL
A6: VA Code SS56-585.5 RPS schedule -- gas allowance shrinks year by year (41% clean required by 2030, 59% by 2035, 79% by 2040, ~100% by 2045)
A7: -- rather than holding stringency fixed. Four checkpoint years (2030, 2035, 2040, 2044.5) were EACH independently, fully re-solved via true
A8: hourly LP dispatch (8,760 hours, 2016-17 hydrological-year weather -- the min-max-robust weather year identified in Appendix N) at CURRENT
A9: cost assumptions (solar CAPEX $1,474/kW 2026 base, O&M $24/kW-yr -- see Assumptions tab). This is a FULL RE-SOLVE, not a re-pricing of old
A10: build sizes -- the optimal mix (how much solar vs. gas vs. storage) is free to shift in response to the updated costs, and it does: at 2030
A11: specifically, the higher solar cost flips the RPS gas constraint from non-binding to binding, cutting the optimal solar build by ~80% versus
A12: the prior (stale-cost) solve. Intermediate years (2027-2029, 2031-2034, etc.) are PIECEWISE-LINEAR interpolated between checkpoints for all
A13: physical quantities (solar MW, sodium MW/MWh, iron-air MWh, gas GWh, export revenue) -- deliberately NOT smoothed. An earlier attempt at a
... A19: CHECKPOINT BUILD SIZES (LP-solved, verified against energy balance to <1e-6 MW)
A20: Year | B20: Solar MW | C20: Na Power MW | D20: Na Energy MWh | E20: FE MWh | F20: Gas %
A21: 2030 | B21: 33548 | C21: 19625 | D21: 140212 | E21: 0 | F21: 46.32
A22: 2035 | B22: 45676 | C22: 36364 | D22: 207183 | E22: 0 | F22: 33.77
A23: 2040 | B23: 56213 | C23: 76318 | D23: 259613 | E23: 0 | F23: 17.37
A24: 2045 (Apr 2045-Mar 2046) | B24: 137738 | C24: 203103 | D24: 632388 | E24: 2551758 | F24: 0.1
A26: FULL 2026-2045 ANNUAL STREAM (piecewise-linear interpolated, net cost = capex+O&M + gas - export revenue)
A27: Year | B27: Solar MW | C27: Na Power MW | D27: FE MWh | E27: Net Cost $M
A28: 2026 | B28: 0 | C28: 0 | D28: 0 | E28: 0
A29: 2027 | B29: 8387 | C29: 4906 | D29: 0 | E29: 977.3
A30: 2028 | B30: 16774 | C30: 9812 | D30: 0 | E30: 1954.6
A31: 2029 | B31: 25161 | C31: 14719 | D31: 0 | E31: 2931.9
A32: 2030 | B32: 33548 | C32: 19625 | D32: 0 | E32: 3909.2
A33: 2031 | B33: 35974 | C33: 22973 | D33: 0 | E33: 4322.7
A34: 2032 | B34: 38399 | C34: 26321 | D34: 0 | E34: 4736.2
A35: 2033 | B35: 40825 | C35: 29668 | D35: 0 | E35: 5149.7
A36: 2034 | B36: 43250 | C36: 33016 | D36: 0 | E36: 5563.2
A37: 2035 | B37: 45676 | C37: 36364 | D37: 0 | E37: 5976.7
A38: 2036 | B38: 47783 | C38: 44355 | D38: 0 | E38: 6269.2
A39: 2037 | B39: 49891 | C39: 52346 | D39: 0 | E39: 6561.7
... A47: 2045 | B47: 137738 | C47: 203103 | D47: 2551758 | E47: 18607.1
A49: RESULT
A50: PV total cost, 2026-2045 @ 4.5% WACC ($M) | B50: =SUMPRODUCT(E28:E47,1/(1.045^(ROW(E28:E47)-ROW(E28)))) -> 80620.313
A51: PV total demand, 2026-2045 @ 4.5% WACC (GWh) | B51: =119818/(1.045^0)+125136/(1.045^1)+130462/(1.045^2)+135796/(1.045^3)+141138/(1.045^4)+146489/(1.045^5)+151848/(1.045^6)+157216/(1.045^7)+162592/(1.045^8)+163469/(1.045^9)+164355/(1.045^10)+165249/(1.045^11)+166153/(1.045^12)+167065/(1.045^13)+167987/(1.045^14)+168918/(1.045^15)+169858/(1.045^16)+170808/(1.045^17)+171767/(1.045^18)+172736/(1.045^19) -> 2065725.6
A52: SLCOE, hourly-verified RPS-compliance trajectory ($/MWh) | B52: =B50*1000/B51 -> 39.0276
A54: For comparison: Scenario1 (annual model, CF-based sizing) SLCOE = $51.67/MWh -- the ~24.5% gap is the quantified
A55: cost of CF-based sizing's structural overbuild relative to genuine hourly-verified dispatch (see Appendix N.6-N.7).

Sheet Scenario3
A1: Scenario 3 — Hourly-Verified, RPS-Compliance Trajectory (2026-2045)
A2: Same methodology as Scenario1, with Scenario 3's DSM-adjusted demand
A4: METHODOLOGY NOTE
A5: Identical methodology to Scenario1 -- see that tab for full detail. Only change: hourly demand is Scenario 3's DSM-adjusted
A6: demand, not Scenario 1's raw demand. Same weather year (2016-17), same RPS-aligned gas schedule per checkpoint, same full re-solve at
A7: current cost assumptions (solar CAPEX $1,474/kW 2026 base, O&M $24/kW-yr), same piecewise-linear interpolation throughout (including
A8: solar -- not smoothed, consistent with the fix applied after Scenario 1's spline-overshoot bug).
A10: CHECKPOINT BUILD SIZES (LP-solved, verified against energy balance to <1e-6 MW)
A11: Year | B11: Solar MW | C11: Na Power MW | D11: Na Energy MWh | E11: FE MWh | F11: Gas %
A12: 2030 | B12: 33224 | C12: 19446 | D12: 138942 | E12: 0 | F12: 46.14
A13: 2035 | B13: 44778 | C13: 35783 | D13: 203085 | E13: 0 | F13: 33.53
A14: 2040 | B14: 53645 | C14: 70553 | D14: 247623 | E14: 0 | F14: 17.21
A15: 2045 (Apr 2045-Mar 2046) | B15: 130321 | C15: 190322 | D15: 599355 | E15: 2404364 | F15: 0.1
A17: FULL 2026-2045 ANNUAL STREAM (piecewise-linear interpolated)
A18: Year | B18: Solar MW | C18: Na Power MW | D18: FE MWh | E18: Net Cost $M
A19: 2026 | B19: 0 | C19: 0 | D19: 0 | E19: 0
A20: 2027 | B20: 8306 | C20: 4862 | D20: 0 | E20: 963.3
A21: 2028 | B21: 16612 | C21: 9723 | D21: 0 | E21: 1926.5
A22: 2029 | B22: 24918 | C22: 14584 | D22: 0 | E22: 2889.8
A23: 2030 | B23: 33224 | C23: 19446 | D23: 0 | E23: 3853.1
A24: 2031 | B24: 35535 | C24: 22713 | D24: 0 | E24: 4244.4
A25: 2032 | B25: 37846 | C25: 25981 | D25: 0 | E25: 4635.7
A26: 2033 | B26: 40156 | C26: 29248 | D26: 0 | E26: 5026.9
A27: 2034 | B27: 42467 | C27: 32516 | D27: 0 | E27: 5418.2
A28: 2035 | B28: 44778 | C28: 35783 | D28: 0 | E28: 5809.5
A29: 2036 | B29: 46551 | C29: 42737 | D29: 0 | E29: 6067.1
A30: 2037 | B30: 48325 | C30: 49691 | D30: 0 | E30: 6324.7
... A38: 2045 | B38: 130321 | C38: 190322 | D38: 2404364 | E38: 17462.9
A40: RESULT
A41: PV total cost, 2026-2045 @ 4.5% WACC ($M) | B41: =SUMPRODUCT(E19:E38,1/(1.045^(ROW(E19:E38)-ROW(E19)))) -> 77340.229
A42: PV total demand, 2026-2045 @ 4.5% WACC (GWh) | B42: =119818/(1.045^0)+124821.1/(1.045^1)+129825.9/(1.045^2)+134832.3/(1.045^3)+139840.2/(1.045^4)+144839.5/(1.045^5)+149839.8/(1.045^6)+154842.2/(1.045^7)+159845.4/(1.045^8)+160342.4/(1.045^9)+160816.1/(1.045^10)+161289.8/(1.045^11)+161765.5/(1.045^12)+162241/(1.045^13)+162718.2/(1.045^14)+163278.7/(1.045^15)+163841.3/(1.045^16)+164407/(1.045^17)+164974.5/(1.045^18)+165544.9/(1.045^19) -> 2026281.6
A43: SLCOE, hourly-verified RPS-compliance trajectory ($/MWh) | B43: =B41*1000/B42 -> 38.168548
A45: For comparison: Scenario3 (annual model, CF-based sizing) SLCOE = $49.11/MWh; Scenario1 = $39.03/MWh; Scenario1B = $37.60/MWh.

Sheet Scenario2_Base
A1: Scenario 2 — Base Case (Deloitte gas price), Hourly-Verified (2026-2045)
A2: First of three gas-price tiers (Low/EIA and High/Hughes-Post Carbon Institute 2021 to follow)
A4: METHODOLOGY NOTE — read before using this tab
A5: STRUCTURALLY DIFFERENT from Scenario1/3. Solar and storage are NOT decision variables here -- they are fixed at a linear buildout:
A6: solar/wind ramps to the 16,100 MW statutory floor by 2035 (Va. Code SS56-585.5(D)(2)), then holds flat; both storage types (sodium-ion 16,000 MW,
A7: iron-air 3,480 MW LDES, Va. HB895/SB448) ramp linearly all the way to their own 2045 target, with no flat period. CCGT capacity is sized
A8: DIRECTLY to cover each checkpoint's worst single hourly gap (demand minus nuclear, existing solar, CVOW wind, and the VCEA solar target),
A9: crediting storage with ZERO contribution -- a deliberately conservative simplification, not a full optimization of CCGT size jointly with
A10: storage pre-positioning (that would require its own small LP and was set aside to conserve session budget). Only dispatch is optimized by the LP:
A11: given fixed capacities, when to run gas vs. storage each hour. Gas price is Deloitte's published path ($3.70/MMBtu 2026 -> $5.40 (2030) ->
A12: $6.35 (2040) -> $7.50 (2050, extrapolated beyond Deloitte's own published figure)), converted to $/MWh via a 6.4 MMBtu/MWh heat rate, plus
A13: $3/MWh CCGT variable O&M. Sodium-ion duration assumed at 4 hours (NREL ATB standard reference) -- unlike Scenarios 1/3, nothing in the source
... A25: CHECKPOINT SIZING (LP-solved dispatch; capacities fixed externally per methodology note)
A26: Year | B26: Solar MW | C26: CCGT MW | D26: Gas GWh | E26: Gas Rate $/MWh
A27: 2030 | B27: 10000 | C27: 14137.2 | D27: 76166.2 | E27: 37.56
A28: 2035 | B28: 16100 | C28: 16758.2 | D28: 87824.5 | E28: 40.6
A29: 2040 | B29: 16100 | C29: 17351.1 | D29: 92524.5 | E29: 43.64
A30: 2045 (Apr 2045-Mar 2046) | B30: 16100 | C30: 18319.7 | D30: 97473.9 | E30: 47.32
A32: FULL 2026-2045 ANNUAL STREAM (piecewise-linear interpolated; includes solar+storage+CCGT capex/O&M and gas fuel cost)
A33: Year | B33: Solar MW | C33: CCGT MW | D33: Gas GWh | E33: Net Cost $M
A34: 2026 | B34: 0 | C34: 0 | D34: 0 | E34: 0
A35: 2027 | B35: 2500 | C35: 3534 | D35: 19042 | E35: 1736.2
A36: 2028 | B36: 5000 | C36: 7068 | D36: 38083 | E36: 3472.3
A37: 2029 | B37: 7500 | C37: 10603 | D37: 57124 | E37: 5208.5
A38: 2030 | B38: 10000 | C38: 14137 | D38: 76166 | E38: 6944.7
A39: 2031 | B39: 11220 | C39: 14661 | D39: 78498 | E39: 7360.2
A40: 2032 | B40: 12440 | C40: 15185 | D40: 80830 | E40: 7775.7
A41: 2033 | B41: 13660 | C41: 15710 | D41: 83161 | E41: 8191.1
A42: 2034 | B42: 14880 | C42: 16234 | D42: 85493 | E42: 8606.6
A43: 2035 | B43: 16100 | C43: 16758 | D43: 87825 | E43: 9022.1
A44: 2036 | B44: 16100 | C44: 16877 | D44: 88765 | E44: 9146.3
A45: 2037 | B45: 16100 | C45: 16995 | D45: 89705 | E45: 9270.4
... A53: 2045 | B53: 16100 | C53: 18320 | D53: 97474 | E53: 10336.5
A55: RESULT
A56: PV total cost, 2026-2045 @ 4.5% WACC ($M) | B56: =SUMPRODUCT(E34:E53,1/(1.045^(ROW(E34:E53)-ROW(E34)))) -> 96783.511
A57: PV total demand, 2026-2045 @ 4.5% WACC (GWh) | B57: =119818/(1.045^0)+125136/(1.045^1)+130462/(1.045^2)+135796/(1.045^3)+141138/(1.045^4)+146489/(1.045^5)+151848/(1.045^6)+157216/(1.045^7)+162592/(1.045^8)+163469/(1.045^9)+164355/(1.045^10)+165249/(1.045^11)+166153/(1.045^12)+167065/(1.045^13)+167987/(1.045^14)+168918/(1.045^15)+169858/(1.045^16)+170808/(1.045^17)+171767/(1.045^18)+172736/(1.045^19) -> 2065725.6
A58: SLCOE, Scenario 2 base case (Deloitte gas), hourly-verified ($/MWh) | B58: =B56*1000/B57 -> 46.852065
A60: For comparison: Scenario1 = $39.03/MWh; Scenario3 = $30.97/MWh. Low (EIA) and High (Hughes/Post
A61: Carbon Institute, 2021 -- less current, to be caveated) gas-price tiers not yet built; this tab covers the Deloitte base case only.

Sheet Scenario3B
A1: Scenario 3B — Mostly-RPS-Compliant, Flat at 95% (Hourly-Verified, 2026-2045)
A2: Follows the real RPS schedule like Scenario 3, except gas is floored at 5% rather than continuing to ~0% by 2045
A4: METHODOLOGY NOTE — read before using this tab
A5: 3B is NOT a flat-5%-throughout scenario (that would badly overstate its stringency in early years -- see the 2030 sanity-check discussion:
A6: the real RPS-required gas allowance in 2030 is 46.15%, far more permissive than a flat 5% cap would imply). Instead, 3B follows Dominion's
A7: actual RPS schedule exactly, year by year, UNTIL that schedule would require going below 5% gas -- at which point it holds flat at 5%
A8: rather than continuing toward RPS's eventual ~100% (0.1% gas) requirement. Since RPS itself puts 2044 at 95% clean (5% gas) already, and
A9: 2045 at 100% (which 3B refuses to follow), the entire 2044.5 blended terminal checkpoint correctly uses a flat 5% cap.
A11: PRACTICAL CONSEQUENCE: the 2030, 2035, and 2040 checkpoints are IDENTICAL to Scenario 3's own RPS-realistic solves (59%, 41%, and
A12: 17.25% gas respectively -- all well above the 5% floor, so RPS is the binding constraint, not 3B's cap) -- reused directly, not re-solved.
A13: Only the 2044.5 terminal checkpoint required a new solve, at a flat 5% cap instead of Scenario 3s 0% terminal. Same current-cost assumptions
A14: throughout (solar CAPEX $1,474/kW 2026 base, O&M $24/kW-yr), same piecewise-linear interpolation for all physical quantities (not smoothed),
... A17: CHECKPOINT BUILD SIZES (LP-solved, verified against energy balance to <1e-6 MW)
A18: Year | B18: Solar MW | C18: Na Power MW | D18: Na Energy MWh | E18: FE MWh | F18: Gas % | G18: Constraint
A19: 2030 | B19: 33224 | C19: 19446 | D19: 138942 | E19: 0 | F19: 46.15 | G19: RPS (46.15%)
A20: 2035 | B20: 44778 | C20: 35783 | D20: 203085 | E20: 0 | F20: 33.56 | G20: RPS (33.56%)
A21: 2040 | B21: 53645 | C21: 70553 | D21: 247623 | E21: 0 | F21: 17.25 | G21: RPS (17.25%)
A22: 2045 (Apr 2045-Mar 2046, 5% gas) | B22: 98499 | C22: 256668 | D22: 464509 | E22: 131712 | F22: 5 | G22: 3B floor (5%)
A24: FULL 2026-2045 ANNUAL STREAM (piecewise-linear interpolated)
A25: Year | B25: Solar MW | C25: Na Power MW | D25: FE MWh | E25: Net Cost $M
A26: 2026 | B26: 0 | C26: 0 | D26: 0 | E26: 0
A27: 2027 | B27: 8306 | C27: 4862 | D27: 0 | E27: 963.3
A28: 2028 | B28: 16612 | C28: 9723 | D28: 0 | E28: 1926.5
A29: 2029 | B29: 24918 | C29: 14584 | D29: 0 | E29: 2889.8
A30: 2030 | B30: 33224 | C30: 19446 | D30: 0 | E30: 3853.1
A31: 2031 | B31: 35535 | C31: 22713 | D31: 0 | E31: 4244.4
A32: 2032 | B32: 37846 | C32: 25981 | D32: 0 | E32: 4635.7
A33: 2033 | B33: 40156 | C33: 29248 | D33: 0 | E33: 5026.9
A34: 2034 | B34: 42467 | C34: 32516 | D34: 0 | E34: 5418.2
A35: 2035 | B35: 44778 | C35: 35783 | D35: 0 | E35: 5809.5
A36: 2036 | B36: 46551 | C36: 42737 | D36: 0 | E36: 6067.1
A37: 2037 | B37: 48325 | C37: 49691 | D37: 0 | E37: 6324.7
... A45: 2045 | B45: 98499 | C45: 256668 | D45: 131712 | E45: 11061.2
A47: RESULT
A48: PV total cost, 2026-2045 @ 4.5% WACC ($M) | B48: =SUMPRODUCT(E26:E45,1/(1.045^(ROW(E26:E45)-ROW(E26)))) -> 74566.36
A49: PV total demand, 2026-2045 @ 4.5% WACC (GWh) | B49: =119818/(1.045^0)+124821.1/(1.045^1)+129825.9/(1.045^2)+134832.3/(1.045^3)+139840.2/(1.045^4)+144839.5/(1.045^5)+149839.8/(1.045^6)+154842.2/(1.045^7)+159845.4/(1.045^8)+160342.4/(1.045^9)+160816.1/(1.045^10)+161289.8/(1.045^11)+161765.5/(1.045^12)+162241/(1.045^13)+162718.2/(1.045^14)+163278.7/(1.045^15)+163841.3/(1.045^16)+164407/(1.045^17)+164974.5/(1.045^18)+165544.9/(1.045^19) -> 2026281.6
A50: SLCOE, Scenario 3B, hourly-verified ($/MWh) | B50: =B48*1000/B49 -> 36.799603
A52: For comparison: Scenario1 = $39.03/MWh; Scenario1B = $37.60/MWh; Scenario3 = $38.17/MWh; Scenario2_Base (Deloitte) = $46.85/MWh.
A53: 3B comes in below Scenario 3 because it never pays for the expensive final approach toward ~100% clean that Scenario 3 requires by 2044/45.

Sheet Scenario3C
A1: Scenario 3C -- Unconstrained, Cost-Optimized Gas/Clean Mix (2026-2045)
A2: NOT an RPS-compliance scenario -- no RPS gas cap applied. See full methodology note at bottom of sheet.
A4: METHODOLOGY NOTE (SHORT, CORRECTED -- see full note below row 47 for complete detail)
A5: RPS gas-share constraint removed; gas-sourced export disabled. Gas dispatch capped at the data-verified EXISTING Dominion gas
A6: fleet capacity (time-varying as plants retire) -- NOT unconstrained. CORRECTED from an earlier version that allowed unlimited
A7: gas dispatch, self-contradictory since it implied new gas builds while claiming zero CAPEX. Substantial new solar/storage IS
A8: cost-justified once gas is properly capped. SLCOE = $53.11/MWh -- now the HIGHEST of all six scenarios, not the lowest.
A10: CHECKPOINT BUILD SIZES (LP-solved, verified against energy balance to <1e-6 MW)
A11: Year | B11: Solar MW | C11: Na Power MW | D11: Na Energy MWh | E11: FE MWh | F11: Gas %
A12: 2030 | B12: 38211 | C12: 23937 | D12: 545832 | E12: 6309 | F12: 46.14
A13: 2035 | B13: 65407 | C13: 59426 | D13: 1327478 | E13: 10484 | F13: 33.53
A14: 2040 | B14: 68259 | C14: 66607 | D14: 1299068 | E14: 10835.4 | F14: 17.21
A15: 2045 (Apr 2045-Mar 2046) | B15: 90140 | C15: 124170 | D15: 1703443 | E15: 13986.9 | F15: 0.1
A17: FULL 2026-2045 ANNUAL STREAM (piecewise-linear interpolated)
A18: Year | B18: Solar MW | C18: Na Power MW | D18: FE MWh | E18: Net Cost $M
A19: 2026 | B19: 0 | C19: 0 | D19: 0 | E19: 0
A20: 2027 | B20: 9553 | C20: 5984 | D20: 136458 | E20: 1577.2
A21: 2028 | B21: 19106 | C21: 11968 | D21: 272916 | E21: 3154.5
A22: 2029 | B22: 28658 | C22: 17953 | D22: 409374 | E22: 4731.8
A23: 2030 | B23: 38211 | C23: 23937 | D23: 545832 | E23: 6309
A24: 2031 | B24: 43650 | C24: 31035 | D24: 702161 | E24: 7144
A25: 2032 | B25: 49089 | C25: 38133 | D25: 858490 | E25: 7979
A26: 2033 | B26: 54529 | C26: 45230 | D26: 1014820 | E26: 8814
A27: 2034 | B27: 59968 | C27: 52328 | D27: 1171149 | E27: 9649
A28: 2035 | B28: 65407 | C28: 59426 | D28: 1327478 | E28: 10484
A29: 2036 | B29: 65977 | C29: 60862 | D29: 1321796 | E29: 10554.3
A30: 2037 | B30: 66548 | C30: 62298 | D30: 1316114 | E30: 10624.6
... A38: 2045 | B38: 90140 | C38: 124170 | D38: 1703443 | E38: 13986.9
A40: RESULT
A41: PV total cost, 2026-2045 @ 4.5% WACC ($M) | B41: =SUMPRODUCT(E19:E38,1/(1.045^(ROW(E19:E38)-ROW(E19)))) -> 107621.73
A42: PV total demand, 2026-2045 @ 4.5% WACC (GWh) | B42: =119818/(1.045^0)+124821.1/(1.045^1)+129825.9/(1.045^2)+134832.3/(1.045^3)+139840.2/(1.045^4)+144839.5/(1.045^5)+149839.8/(1.045^6)+154842.2/(1.045^7)+159845.4/(1.045^8)+160342.4/(1.045^9)+160816.1/(1.045^10)+161289.8/(1.045^11)+161765.5/(1.045^12)+162241/(1.045^13)+162718.2/(1.045^14)+163278.7/(1.045^15)+163841.3/(1.045^16)+164407/(1.045^17)+164974.5/(1.045^18)+165544.9/(1.045^19) -> 2026281.6
A43: SLCOE, Scenario 3C (cost-optimized gas/clean mix, gas capped at data-verified existing fleet capacity), hourly-verified ($/MWh) | B43: =B41*1000/B42 -> 53.112917
A45: For comparison: Scenario3 (annual model, CF-based sizing) SLCOE = $49.11/MWh; Scenario1 = $39.03/MWh; Scenario1B = $37.60/MWh.
A47: FULL METHODOLOGY NOTE (CORRECTED VERSION)
A48: PRIOR VERSION, NOW SUPERSEDED: an earlier build of this scenario allowed unconstrained gas dispatch (SLCOE=$23.45/MWh),
A49: discovered to be self-contradictory -- it required gas capacity far exceeding any plausible existing fleet (peak dispatch
A50: 13,966-17,429 MW across checkpoints) while simultaneously assuming zero CAPEX, appropriate only for already-existing,
A51: sunk capacity. This version corrects that by capping gas at a data-verified existing-fleet capacity instead.
A53: EXISTING GAS FLEET, DATA SOURCES: 7 plants identified via EIA plant listings (Chesterfield, Bear Garden, Brunswick County,
A54: Greensville, Warren County, Gordonsville, Tenaska Virginia). Commissioning dates and capacity cross-checked directly
...

Sheet Scenario2_Low
A1: Scenario 2 — Low Case (EIA gas price), Hourly-Verified (2026-2045)
A2: Second of three gas-price tiers. Identical to Scenario2_Base except gas price path; see that tab for full structural methodology.
A4: METHODOLOGY NOTE
A5: All physical capacities (solar, storage, CCGT) and gas DISPATCH VOLUMES (GWh) are IDENTICAL to Scenario2_Base -- not re-solved. This is a real
A6: mathematical property of this formulation, not an approximation: storage carries zero marginal cost in the objective and export is bounded to
A7: zero, so the LP always prefers free storage over any positive-cost gas dispatch REGARDLESS of the specific gas price. Only the resulting cost
A8: changes with price, not the dispatch pattern itself. Gas price: EIA reference path ($3.70/MMBtu 2026 -> $3.80 (2030) -> $4.20 (2040) -> $4.95
A9: (2050)), converted to $/MWh via the same 6.4 MMBtu/MWh heat rate, plus $3/MWh CCGT variable O&M.
A11: CHECKPOINT GAS PRICING (physical build sizes identical to Scenario2_Base -- see that tab)
A12: Year | B12: Gas GWh (=Base) | C12: EIA Rate $/MWh
A13: 2030 | B13: 76166.2 | C13: 27.32
A14: 2035 | B14: 87824.5 | C14: 28.6
A15: 2040 | B15: 92524.5 | C15: 29.88
A16: 2045 (Apr 2045-Mar 2046) | B16: 97473.9 | C16: 32.28
A18: FULL 2026-2045 ANNUAL STREAM (piecewise-linear interpolated)
A19: Year | B19: Solar MW | C19: CCGT MW | D19: Gas GWh | E19: Net Cost $M
A20: 2026 | B20: 0 | C20: 0 | D20: 0 | E20: 0
A21: 2027 | B21: 2500 | C21: 3534 | D21: 19042 | E21: 1541.2
A22: 2028 | B22: 5000 | C22: 7068 | D22: 38083 | E22: 3082.4
A23: 2029 | B23: 7500 | C23: 10603 | D23: 57124 | E23: 4623.6
A24: 2030 | B24: 10000 | C24: 14137 | D24: 76166 | E24: 6164.8
A25: 2031 | B25: 11220 | C25: 14661 | D25: 78498 | E25: 6525.5
A26: 2032 | B26: 12440 | C26: 15185 | D26: 80830 | E26: 6886.2
A27: 2033 | B27: 13660 | C27: 15710 | D27: 83161 | E27: 7246.8
A28: 2034 | B28: 14880 | C28: 16234 | D28: 85493 | E28: 7607.5
A29: 2035 | B29: 16100 | C29: 16758 | D29: 87825 | E29: 7968.2
A30: 2036 | B30: 16100 | C30: 16877 | D30: 88765 | E30: 8048.5
A31: 2037 | B31: 16100 | C31: 16995 | D31: 89705 | E31: 8128.8
... A39: 2045 | B39: 16100 | C39: 18320 | D39: 97474 | E39: 8870.5
A41: RESULT
A42: PV total cost, 2026-2045 @ 4.5% WACC ($M) | B42: =SUMPRODUCT(E20:E39,1/(1.045^(ROW(E20:E39)-ROW(E20)))) -> 84840.308
A43: PV total demand, 2026-2045 @ 4.5% WACC (GWh) | B43: =119818/(1.045^0)+125136/(1.045^1)+130462/(1.045^2)+135796/(1.045^3)+141138/(1.045^4)+146489/(1.045^5)+151848/(1.045^6)+157216/(1.045^7)+162592/(1.045^8)+163469/(1.045^9)+164355/(1.045^10)+165249/(1.045^11)+166153/(1.045^12)+167065/(1.045^13)+167987/(1.045^14)+168918/(1.045^15)+169858/(1.045^16)+170808/(1.045^17)+171767/(1.045^18)+172736/(1.045^19) -> 2065725.6
A44: SLCOE, Scenario 2 Low case (EIA gas), hourly-verified ($/MWh) | B44: =B42*1000/B43 -> 41.070463
A46: For comparison: Scenario2_Base (Deloitte) = $46.85/MWh. High (Hughes/Post Carbon Institute, 2021 -- less current,
A47: to be caveated) tier not yet built.

Sheet Scenario2_High
A1: Scenario 2 — Low Case (EIA gas price), Hourly-Verified (2026-2045)
A2: Second of three gas-price tiers. Identical to Scenario2_Base except gas price path; see that tab for full structural methodology.
A4: METHODOLOGY NOTE
A5: All physical capacities (solar, storage, CCGT) and gas DISPATCH VOLUMES (GWh) are IDENTICAL to Scenario2_Base -- not re-solved. This is a real
A6: mathematical property of this formulation, not an approximation: storage carries zero marginal cost in the objective and export is bounded to
A7: zero, so the LP always prefers free storage over any positive-cost gas dispatch REGARDLESS of the specific gas price. Only the resulting cost
A8: changes with price, not the dispatch pattern itself. Gas price: EIA reference path ($3.70/MMBtu 2026 -> $3.80 (2030) -> $4.20 (2040) -> $4.95
A9: (2050)), converted to $/MWh via the same 6.4 MMBtu/MWh heat rate, plus $3/MWh CCGT variable O&M.
A11: CHECKPOINT GAS PRICING (physical build sizes identical to Scenario2_Base -- see that tab)
A12: Year | B12: Gas GWh (=Base) | C12: Hughes Rate $/MWh
A13: 2030 | B13: 76166.2 | C13: 30.31
A14: 2035 | B14: 87824.5 | C14: 37.99
A15: 2040 | B15: 92524.5 | C15: 47.83
A16: 2045 (Apr 2045-Mar 2046) | B16: 97473.9 | C16: 60.44
A18: FULL 2026-2045 ANNUAL STREAM (piecewise-linear interpolated)
A19: Year | B19: Solar MW | C19: CCGT MW | D19: Gas GWh | E19: Net Cost $M
A20: 2026 | B20: 0 | C20: 0 | D20: 0 | E20: 0
A21: 2027 | B21: 2500 | C21: 3534 | D21: 19042 | E21: 1598.2
A22: 2028 | B22: 5000 | C22: 7068 | D22: 38083 | E22: 3196.3
A23: 2029 | B23: 7500 | C23: 10603 | D23: 57124 | E23: 4794.5
A24: 2030 | B24: 10000 | C24: 14137 | D24: 76166 | E24: 6392.7
A25: 2031 | B25: 11220 | C25: 14661 | D25: 78498 | E25: 6872.8
A26: 2032 | B26: 12440 | C26: 15185 | D26: 80830 | E26: 7352.9
A27: 2033 | B27: 13660 | C27: 15710 | D27: 83161 | E27: 7832.9
A28: 2034 | B28: 14880 | C28: 16234 | D28: 85493 | E28: 8313
A29: 2035 | B29: 16100 | C29: 16758 | D29: 87825 | E29: 8793.1
A30: 2036 | B30: 16100 | C30: 16877 | D30: 88765 | E30: 9040.7
A31: 2037 | B31: 16100 | C31: 16995 | D31: 89705 | E31: 9288.3
... A39: 2045 | B39: 16100 | C39: 18320 | D39: 97474 | E39: 11615.7
A41: RESULT
A42: PV total cost, 2026-2045 @ 4.5% WACC ($M) | B42: =SUMPRODUCT(E20:E39,1/(1.045^(ROW(E20:E39)-ROW(E20)))) -> 96768.924
A43: PV total demand, 2026-2045 @ 4.5% WACC (GWh) | B43: =119818/(1.045^0)+125136/(1.045^1)+130462/(1.045^2)+135796/(1.045^3)+141138/(1.045^4)+146489/(1.045^5)+151848/(1.045^6)+157216/(1.045^7)+162592/(1.045^8)+163469/(1.045^9)+164355/(1.045^10)+165249/(1.045^11)+166153/(1.045^12)+167065/(1.045^13)+167987/(1.045^14)+168918/(1.045^15)+169858/(1.045^16)+170808/(1.045^17)+171767/(1.045^18)+172736/(1.045^19) -> 2065725.6
A44: SLCOE, Scenario 2 High case (Hughes/Post Carbon Institute gas), hourly-verified ($/MWh) | B44: =B42*1000/B43 -> 46.845004
A46: For comparison: Scenario2_Base (Deloitte) = $46.85/MWh; Scenario2_Low (EIA) = $41.07/MWh.
A47: to be caveated) tier not yet built.
A48: IMPORTANT, COUNTERINTUITIVE RESULT -- read before citing: Scenario2_High's PV-weighted SLCOE ($46.85/MWh) is virtually identical to Scenario2_Base's ($46.85/MWh), NOT clearly higher as the "High" label might suggest. This is a real, correct consequence of the underlying gas-price shape, not an error: Hughes/Post Carbon Institute's compound-growth trajectory starts BELOW both Deloitte and EIA in 2026 (its own sourced starting point, $3.50/MMBtu, is lower than the shared $3.70 baseline) and does not overtake Deloitte until somewhere between 2035-2040. Combined with PV discounting, which weights near-term years far more heavily than later ones, the years where Hughes prices below Deloitte substantially offset the years where it prices above -- leaving the PV-weighted total nearly unchanged versus Medium, even though Hughes reaches $57/MWh by 2045 versus Deloitte's $44/MWh at the same year (see checkpoint gas pricing table above). Anyone citing this figure as "the high case" should be aware it does not mean "higher cost throughout" -- only "higher cost in later years, roughly offset by lower cost in earlier years."

Sheet Scenario1B
A1: Scenario 1B — Mostly-RPS-Compliant, Flat at 95% (Hourly-Verified, 2026-2045)
A2: Same definition as Scenario 3B, without DSM demand -- see that tab for full methodology
A4: METHODOLOGY NOTE
A5: Identical structure to Scenario3B_HourlyRPS: follows Dominion's actual RPS schedule year by year until it would require going below 5%
A6: gas, then holds flat at 5% rather than continuing to ~100% by 2045. Uses Scenario 1's raw (non-DSM) demand throughout.
A8: 2030, 2035, and 2040 are IDENTICAL to Scenario 1's own RPS-realistic solves (59%, 41%, and 21% gas respectively -- all well above
A9: the 5% floor, so RPS is the binding constraint, not this scenario's cap) -- reused directly, not re-solved. Only the 2044.5 terminal
A10: checkpoint required a new solve, at a flat 5% cap instead of Scenario 1s 0% terminal.
A12: CORRECTION NOTE: an earlier attempt at this tab used a flat 5% cap at every checkpoint including 2030-2040, which badly overstates
A13: stringency in those years (RPS's actual 2030 requirement is 46.34% gas, far more permissive). This was caught by the same sanity check
A14: that first caught it for 3B, and corrected the same way before this tab was built -- the flawed version was never captured to the workbook.
A16: CHECKPOINT BUILD SIZES (LP-solved, verified against energy balance to <1e-6 MW)
A17: Year | B17: Solar MW | C17: Na Power MW | D17: Na Energy MWh | E17: FE MWh | F17: Gas % | G17: Constraint
A18: 2030 | B18: 33548 | C18: 19625 | D18: 140212 | E18: 0 | F18: 46.34 | G18: RPS (46.34%)
A19: 2035 | B19: 45676 | C19: 36364 | D19: 207183 | E19: 0 | F19: 33.79 | G19: RPS (33.79%)
A20: 2040 | B20: 56213 | C20: 76318 | D20: 259613 | E20: 0 | F20: 17.4 | G20: RPS (17.40%)
A21: 2045 (Apr 2045-Mar 2046, 5% gas) | B21: 104498 | C21: 275821 | D21: 492971 | E21: 131641 | F21: 5 | G21: 1B floor (5%)
A23: FULL 2026-2045 ANNUAL STREAM (piecewise-linear interpolated)
A24: Year | B24: Solar MW | C24: Na Power MW | D24: FE MWh | E24: Net Cost $M
A25: 2026 | B25: 0 | C25: 0 | D25: 0 | E25: 0
A26: 2027 | B26: 8387 | C26: 4906 | D26: 0 | E26: 977.3
A27: 2028 | B27: 16774 | C27: 9812 | D27: 0 | E27: 1954.6
A28: 2029 | B28: 25161 | C28: 14719 | D28: 0 | E28: 2931.9
A29: 2030 | B29: 33548 | C29: 19625 | D29: 0 | E29: 3909.2
A30: 2031 | B30: 35974 | C30: 22973 | D30: 0 | E30: 4322.7
A31: 2032 | B31: 38399 | C31: 26321 | D31: 0 | E31: 4736.2
A32: 2033 | B32: 40825 | C32: 29668 | D32: 0 | E32: 5149.7
A33: 2034 | B33: 43250 | C33: 33016 | D33: 0 | E33: 5563.2
A34: 2035 | B34: 45676 | C34: 36364 | D34: 0 | E34: 5976.7
A35: 2036 | B35: 47783 | C35: 44355 | D35: 0 | E35: 6269.2
A36: 2037 | B36: 49891 | C36: 52346 | D36: 0 | E36: 6561.7
... A44: 2045 | B44: 104498 | C44: 275821 | D44: 131641 | E44: 11821.9
A46: RESULT
A47: PV total cost, 2026-2045 @ 4.5% WACC ($M) | B47: =SUMPRODUCT(E25:E44,1/(1.045^(ROW(E25:E44)-ROW(E25)))) -> 77680.274
A48: PV total demand, 2026-2045 @ 4.5% WACC (GWh) | B48: =119818/(1.045^0)+125136/(1.045^1)+130462/(1.045^2)+135796/(1.045^3)+141138/(1.045^4)+146489/(1.045^5)+151848/(1.045^6)+157216/(1.045^7)+162592/(1.045^8)+163469/(1.045^9)+164355/(1.045^10)+165249/(1.045^11)+166153/(1.045^12)+167065/(1.045^13)+167987/(1.045^14)+168918/(1.045^15)+169858/(1.045^16)+170808/(1.045^17)+171767/(1.045^18)+172736/(1.045^19) -> 2065725.6
A49: SLCOE, Scenario 1B, hourly-verified ($/MWh) | B49: =B47*1000/B48 -> 37.604352
A51: For comparison: Scenario1 = $39.03/MWh; Scenario3B = $26.53/MWh.

Sheet DER_Owner_Economics
A1: DER Owner Economics — Rooftop & Parking-Lot Solar Owner NPV
A2: Extracted from the former Scenario3 annual-model tab (now deleted) — independent of CF%-based system sizing
A4: METHODOLOGY NOTE: uses simple annual capacity-factor estimates for individual DER unit generation (legitimate, per scope confirmation),
A5: not system-level sizing. Wholesale energy-price input corrected during extraction: real hourly-data-derived duck-curve discount (11.4%,
A6: from the LP-derived price shape) replaces an old flat 40% guess -- $55.80/MWh now, was $37.80/MWh. See row 183 comment for full detail.
